Workbook

Sheet Entrada de Datos
B2: CALCULADORA ROI - COLECTORES DE VIBRACIÓN
B3: A-MAQ S.A. | Mantenimiento Predictivo y Análisis de Vibración
B5: INFORMACIÓN DEL CLIENTE
B6: Nombre de la Empresa | D6: Ej: EPM, Celsia, Postobón
B7: Sector Industrial | D7: Hidroeléctrica, Manufactura, Empaque, Otro
B8: Nombre del Contacto | D8: Persona encargada de mantenimiento
B9: Cargo | D9: Ej: Jefe de Mantenimiento
B10: Teléfono / Email | D10: Datos de contacto
B11: Fecha de Evaluación | D11: DD/MM/AAAA
B13: SELECCIÓN DEL COLECTOR DE VIBRACIÓN
B14: Modelo | C14: Nivel | D14: Precio (COP) | E14: Características
B15: Vidrio | C15: Básico | D15: 21000000 | E15: Colector básico para rutas de inspección estándar
B16: Ba 3 Pro | C16: Intermedio | D16: 68000000 | E16: Colector profesional con análisis avanzado
B17: Ba 5 | C17: Full / Avanzado | D17: 115000000 | E17: Sistema completo de monitoreo y análisis ($110M-$120M)
B19: Modelo Seleccionado | C19: Ba 3 Pro
B20: Inversión Total (COP) | C20: =IF(C19="Vidrio",21000000,IF(C19="Ba 3 Pro",68000000,IF(C19="Ba 5",115000000,0))) -> 68000000 | D20: Para Ba 5: edite manualmente si el precio difiere ($110M-$120M)
B21: Inversión Personalizada (opcional) | D21: Complete solo si desea usar un precio diferente al automático
B23: DATOS OPERACIONALES DE LA PLANTA
B24: Número total de activos (equipos rotativos) en la planta | C24: 120 | D24: Motores, bombas, ventiladores, turbinas, etc.
B25: Cantidad de activos CRÍTICOS (su falla detiene producción) | C25: 25 | D25: Solo aquellos cuya falla genera paro de línea/planta
B26: Costo promedio por hora de paro por activo crítico (COP/hora) | C26: 5000000 | D26: Incluye lucro cesante + producción perdida
B27: Frecuencia actual de fallas no planificadas (paros/año) | C27: 8 | D27: Promedio de eventos de paro no programado al año
B28: Duración promedio de cada paro no planificado (horas) | C28: 12 | D28: Tiempo desde falla hasta restablecimiento completo
B29: Costo promedio de intervención correctiva externa (COP) | C29: 15000000 | D29: Contratación de servicio técnico externo por evento
B30: Número de intervenciones correctivas externas al año | C30: 6 | D30: Cantidad de veces que se contrata servicio externo
B31: Horas-hombre mensuales en mantenimiento reactivo | C31: 160 | D31: Horas del equipo interno dedicadas a reparar fallas
B32: Costo hora-hombre del personal de mantenimiento (COP/h) | C32: 35000 | D32: Incluye prestaciones y carga laboral
B33: Días promedio de demora en obtención de repuestos críticos | C33: 15 | D33: Tiempo de espera desde pedido hasta recepción
B34: Costo promedio del inventario de repuestos críticos (COP/año) | C34: 80000000 | D34: Valor del stock de partes de repuesto mantenido
B35: Horas de paro programado anuales (mantenimiento preventivo) | C35: 200 | D35: Ventanas de mantenimiento que afectan producción
... B37: Facturación mensual de la planta (COP) | C37: 500000000 | D37: Ingreso mensual aproximado para referencia
B39: FACTORES DE MEJORA ESPERADOS (BENCHMARKS DE LA INDUSTRIA)
B40: % Reducción de fallas no planificadas con monitoreo predictivo | C40: 0.5 | D40: Benchmark: 50-75% (DOE, McKinsey)
B41: % Reducción de costos de mantenimiento correctivo | C41: 0.4 | D41: Benchmark: 25-40% (DOE)
B42: % Optimización de horas-hombre (menos reactivo) | C42: 0.35 | D42: Benchmark: 30-60% (PWC)
B43: % Reducción de demoras por repuestos (inventario optimizado) | C43: 0.25 | D43: Benchmark: 20-30% (industria)
B44: % Reducción de paros programados (mejor planificación) | C44: 0.2 | D44: Benchmark: 15-25% (Metrix, Farnell)
B45: % Extensión de vida útil de activos | C45: 0.25 | D45: Benchmark: 20-40% (McKinsey)
B46: % Ahorro en consumo energético por alineación/balanceo | C46: 0.05 | D46: Benchmark: 5-8% (Vista Projects)
B47: % Reducción de riesgos de seguridad / primas de seguro | C47: 0.1 | D47: Benchmark: 5-15% (OPMaint, PWC)
...

Sheet Cálculos Internos
B2: CÁLCULOS INTERNOS - FACTORES DE AHORRO
B4: INVERSIÓN
B5: Inversión Total (COP) | C5: =IF('Entrada de Datos'!C21>0,'Entrada de Datos'!C21,'Entrada de Datos'!C20) -> 68000000
B7: FACTOR 1: REDUCCIÓN DE LUCRO CESANTE POR PAROS NO PLANIFICADOS
B8: Concepto | C8: Valor Actual | D8: Fórmula / Referencia | E8: Con Predictivo | F8: Ahorro Anual
B9: Horas de paro no planificado al año | C9: ='Entrada de Datos'!C27*'Entrada de Datos'!C28 -> 96 | D9: Fallas/año × Horas/falla | E9: =C9*(1-'Entrada de Datos'!C40) -> 48 | F9: =C9-E9 -> 48
B10: Costo total de lucro cesante anual (COP) | C10: =C9*'Entrada de Datos'!C26 -> 480000000 | D10: Horas paro × Costo/hora | E10: =E9*'Entrada de Datos'!C26 -> 240000000 | F10: =C10-E10 -> 240000000
B12: FACTOR 2: REDUCCIÓN DE COSTOS DE MANTENIMIENTO CORRECTIVO EXTERNO
B13: Concepto | C13: Valor Actual | D13: Fórmula / Referencia | E13: Con Predictivo | F13: Ahorro Anual
B14: Costo anual mantenimiento correctivo externo | C14: ='Entrada de Datos'!C29*'Entrada de Datos'!C30 -> 90000000 | D14: Costo/intervención × N° intervenciones | E14: =C14*(1-'Entrada de Datos'!C41) -> 54000000 | F14: =C14-E14 -> 36000000
B16: FACTOR 3: OPTIMIZACIÓN DE HORAS-HOMBRE DE MANTENIMIENTO
B17: Concepto | C17: Valor Actual | D17: Fórmula / Referencia | E17: Con Predictivo | F17: Ahorro Anual
B18: Costo anual HH en mantenimiento reactivo | C18: ='Entrada de Datos'!C31*12*'Entrada de Datos'!C32 -> 67200000 | D18: HH/mes × 12 × Costo/HH | E18: =C18*(1-'Entrada de Datos'!C42) -> 43680000 | F18: =C18-E18 -> 23520000
B20: FACTOR 4: OPTIMIZACIÓN DE INVENTARIO Y REDUCCIÓN DE DEMORAS POR REPUESTOS
B21: Concepto | C21: Valor Actual | D21: Fórmula / Referencia | E21: Con Predictivo | F21: Ahorro Anual
B22: Costo de demoras + sobre-inventario anual | C22: ='Entrada de Datos'!C33*8*'Entrada de Datos'!C26*('Entrada de Datos'!C27*0.3)+'Entrada de Datos'!C34 -> 1520000000 | D22: Días×8h×Costo/h×(30% fallas requieren repuestos) + Inventario | E22: =C22*(1-'Entrada de Datos'!C43) -> 1140000000 | F22: =C22-E22 -> 380000000
B24: FACTOR 5: REDUCCIÓN DE PAROS PROGRAMADOS (VENTANAS DE MANTENIMIENTO)
B25: Concepto | C25: Valor Actual | D25: Fórmula / Referencia | E25: Con Predictivo | F25: Ahorro Anual
B26: Costo anual de producción perdida por paros programados | C26: ='Entrada de Datos'!C35*'Entrada de Datos'!C36 -> 400000000 | D26: Horas paro × Costo/hora producción | E26: =C26*(1-'Entrada de Datos'!C44) -> 320000000 | F26: =C26-E26 -> 80000000
B28: FACTOR 6: EXTENSIÓN DE VIDA ÚTIL DE ACTIVOS (CAPEX DIFERIDO)
B29: Concepto | C29: Valor Actual | D29: Fórmula / Referencia | E29: Con Predictivo | F29: Ahorro Anual
B30: Ahorro anual por diferimiento de reposición de activos | C30: ='Entrada de Datos'!C25*50000000/15 -> 83333333 | D30: N° activos críticos × $50M reposición promedio / 15 años | E30: =C30 -> 83333333 | F30: =C30*'Entrada de Datos'!C45 -> 20833333
B32: FACTOR 7: AHORRO ENERGÉTICO POR CORRECCIÓN DE DESALINEACIÓN Y DESBALANCEO
B33: Concepto | C33: Valor Actual | D33: Fórmula / Referencia | E33: Con Predictivo | F33: Ahorro Anual
B34: Ahorro energético anual estimado | C34: ='Entrada de Datos'!C24*50*0.746*6000*500 -> 13428000000 | D34: Activos × 50HP prom × 0.746kW × 6000h × $500/kWh | E34: =C34 -> 13428000000 | F34: =C34*'Entrada de Datos'!C46 -> 671400000
B36: FACTOR 8: REDUCCIÓN DE RIESGOS DE SEGURIDAD Y PRIMAS DE SEGURO
B37: Concepto | C37: Valor Actual | D37: Fórmula / Referencia | E37: Con Predictivo | F37: Ahorro Anual
B38: Ahorro estimado en seguros y costos por incidentes | C38: ='Entrada de Datos'!C37*12*0.02 -> 120000000 | D38: Facturación anual × 2% (base seguros/seguridad) | E38: =C38 -> 120000000 | F38: =C38*'Entrada de Datos'!C47 -> 12000000
B40: RESUMEN DE AHORROS Y CÁLCULO DE ROI
B42: Factor de Ahorro | C42: Ahorro Anual (COP) | D42: % del Total
B43: 1. Reducción de Lucro Cesante | C43: =F10 -> 240000000 | D43: =IF(C51>0,C43/C51,0) -> 0.16396205
B44: 2. Reducción de Costos Correctivos | C44: =F14 -> 36000000 | D44: =IF(C51>0,C44/C51,0) -> 0.024594308
B45: 3. Optimización de Horas-Hombre | C45: =F18 -> 23520000 | D45: =IF(C51>0,C45/C51,0) -> 0.016068281
B46: 4. Optimización de Inventario / Repuestos | C46: =F22 -> 380000000 | D46: =IF(C51>0,C46/C51,0) -> 0.25960658
B47: 5. Reducción de Paros Programados | C47: =F26 -> 80000000 | D47: =IF(C51>0,C47/C51,0) -> 0.054654017
B48: 6. Extensión de Vida Útil (CAPEX Diferido) | C48: =F30 -> 20833333 | D48: =IF(C51>0,C48/C51,0) -> 0.014232817
B49: 7. Ahorro Energético | C49: =F34 -> 671400000 | D49: =IF(C51>0,C49/C51,0) -> 0.45868384
B50: 8. Reducción de Riesgos / Seguros | C50: =F38 -> 12000000 | D50: =IF(C51>0,C50/C51,0) -> 0.0081981026
B51: AHORRO TOTAL ANUAL | C51: =SUM(C43:C50) -> 1.4637533e+09 | D51: 100%
B53: INVERSIÓN TOTAL | C53: =C5 -> 68000000
...

Sheet Reporte Ejecutivo
B2: REPORTE DE RETORNO DE INVERSIÓN (ROI)
B3: Colectores de Vibración para Mantenimiento Predictivo
B4: A-MAQ S.A. | Especialistas en Análisis de Vibración
B6: INFORMACIÓN DEL CLIENTE
B7: Empresa: | C7: ='Entrada de Datos'!C6 -> 0 | D7: Sector: | E7: ='Entrada de Datos'!C7 -> 0
B8: Contacto: | C8: ='Entrada de Datos'!C8 -> 0 | D8: Fecha: | E8: ='Entrada de Datos'!C11 -> 0
B10: INDICADORES CLAVE DE RETORNO
B11: Modelo Seleccionado | D11: Inversión Total | F11: Ahorro Anual
B12: ='Entrada de Datos'!C19 -> Ba 3 Pro | D12: ='Cálculos Internos'!C5 -> 68000000 | F12: ='Cálculos Internos'!C51 -> 1.4637533e+09
B13: ROI Primer Año | D13: Payback (meses) | F13: Relación B/C
B14: ='Cálculos Internos'!C55 -> 20.525784 | D14: ='Cálculos Internos'!C56 -> 0.6 | F14: ='Cálculos Internos'!C57 -> 21.525784
B16: DESGLOSE DE BENEFICIOS POR CATEGORÍA
B17: Factor de Ahorro | C17: Ahorro Anual (COP) | D17: % del Total | E17: Ahorro Mensual (COP)
B18: Reducción de Lucro Cesante | C18: ='Cálculos Internos'!C43 -> 240000000 | D18: ='Cálculos Internos'!D43 -> 0.16396205 | E18: =C18/12 -> 20000000
B19: Reducción de Costos Correctivos | C19: ='Cálculos Internos'!C44 -> 36000000 | D19: ='Cálculos Internos'!D44 -> 0.024594308 | E19: =C19/12 -> 3000000
B20: Optimización de Horas-Hombre | C20: ='Cálculos Internos'!C45 -> 23520000 | D20: ='Cálculos Internos'!D45 -> 0.016068281 | E20: =C20/12 -> 1960000
B21: Optimización de Inventario/Repuestos | C21: ='Cálculos Internos'!C46 -> 380000000 | D21: ='Cálculos Internos'!D46 -> 0.25960658 | E21: =C21/12 -> 31666667
B22: Reducción de Paros Programados | C22: ='Cálculos Internos'!C47 -> 80000000 | D22: ='Cálculos Internos'!D47 -> 0.054654017 | E22: =C22/12 -> 6666666.7
B23: Extensión de Vida Útil (CAPEX Diferido) | C23: ='Cálculos Internos'!C48 -> 20833333 | D23: ='Cálculos Internos'!D48 -> 0.014232817 | E23: =C23/12 -> 1736111.1
B24: Ahorro Energético | C24: ='Cálculos Internos'!C49 -> 671400000 | D24: ='Cálculos Internos'!D49 -> 0.45868384 | E24: =C24/12 -> 55950000
B25: Reducción de Riesgos / Seguros | C25: ='Cálculos Internos'!C50 -> 12000000 | D25: ='Cálculos Internos'!D50 -> 0.0081981026 | E25: =C25/12 -> 1000000
B26: AHORRO TOTAL | C26: =SUM(C18:C25) -> 1.4637533e+09 | D26: 100% | E26: =C26/12 -> 1.2197944e+08
B60: PROYECCIÓN DE BENEFICIO NETO ACUMULADO A 5 AÑOS
C61: Año 1 | D61: Año 2 | E61: Año 3 | F61: Año 4 | G61: Año 5
B62: Beneficio Neto Acumulado | C62: ='Cálculos Internos'!C62 -> 1.4637533e+09 | D62: ='Cálculos Internos'!D62 -> 2.9275067e+09 | E62: ='Cálculos Internos'!E62 -> 4391260000 | F62: ='Cálculos Internos'!F62 -> 5.8550133e+09 | G62: ='Cálculos Internos'!G62 -> 7.3187667e+09
B63: Ahorro Anual | C63: ='Cálculos Internos'!C59 -> 0 | D63: ='Cálculos Internos'!D59 -> 0 | E63: ='Cálculos Internos'!E59 -> 0 | F63: ='Cálculos Internos'!F59 -> 0 | G63: ='Cálculos Internos'!G59 -> 0
B81: Nota: Los ahorros proyectados se basan en benchmarks de la industria (DOE, McKinsey, PWC) y datos proporcionados por el cliente. Los resultados reales pueden variar.
B82: A-MAQ S.A. | Medellín, Colombia | Mantenimiento Predictivo y Análisis de Vibración | www.amaq.com
B83: Fuentes: U.S. Department of Energy (DOE), McKinsey & Company, PWC Predictive Maintenance 4.0, Metrix Vibration Methodology, Vista Projects ROI Guide
